<?xml version="1.0"?>
<robot name="mrx_t4_a00_new">

  <link name="base_link">
    <visual>
      <origin xyz=" 0 0 -0.01"  rpy="0 0 0"/>
      <geometry>
        <box size="1 1 0.02" />
      </geometry>
      <material name="Brown" />
    </visual>
    <collision>
      <origin xyz=" 0 0 -0.01"  rpy="0 0 0"/>
      <geometry>
        <box size="1 1 0.02" />
      </geometry>
    </collision>
    <inertial>
      <origin xyz="0 0 0" rpy="0 0 0" />
      <inertia ixx="1.0" ixy="0.0" ixz="0.0" iyy="0.5" iyz="0.0" izz="1.0" />
      <mass value="500" />
    </inertial>
  </link>

  <joint name="bottom_joint" type="fixed">
    <origin xyz="0 0 0" rpy="0 0 0" />
    <parent link="base_link"/>
    <child link="base"/>
  </joint>

  <link name="base">
    <inertial>
      <origin xyz="-0.000144936182500289 -0.00820760069399896 0.0989499405919245" rpy="0 0 0" />
      <mass value="2.18102317082151" />
      <inertia
        ixx="0.0113453778745561"
        ixy="4.63289918071108E-05"
        ixz="-4.32363621106919E-06"
        iyy="0.0113991095551259"
        iyz="0.000506283101670542"
        izz="0.00568476675971968" />
    </inertial>
    <visual>
      <origin xyz="0 0 0" rpy="0 0 0" />
      <geometry>
        <mesh filename="package://mrx_t4_a00_new/meshes/base.STL" />
      </geometry>
      <material name="">
        <color rgba="0.752941176470588 0.752941176470588 0.752941176470588 1" />
      </material>
    </visual>
    <collision>
      <origin xyz="0 0 0" rpy="0 0 0" />
      <geometry>
        <mesh filename="package://mrx_t4_a00_new/meshes/base.STL" />
      </geometry>
    </collision>
  </link>

  <joint name="base_to_armA" type="revolute">
    <origin xyz="0 0 0.144" rpy="-1.5708 0 0" />
    <parent link="base" />
    <child link="armA" />
    <axis xyz="0 -1 0" />
    <limit effort="300" velocity="1" lower="-2.967" upper="2.967" />
  </joint>

  <link name="armA">
    <inertial>
      <origin xyz="-0.058992099688719 -0.0186016047995519 0.0758305002441301" rpy="0 0 0" />
      <mass value="0.303896581928651" />
      <inertia
        ixx="0.001050564841006"
        ixy="-1.55163555383218E-05"
        ixz="-6.26787525019475E-05"
        iyy="0.00302129432156541"
        iyz="3.82579698525422E-05"
        izz="0.00299355685876571" />
    </inertial>
    <visual>
      <origin xyz="0 0 0" rpy="0 0 0" />
      <geometry>
        <mesh filename="package://mrx_t4_a00_new/meshes/armA.STL" />
      </geometry>
      <material name="">
        <color rgba="0.752941176470588 0.752941176470588 0.752941176470588 1" />
      </material>
    </visual>
    <collision>
      <origin xyz="0 0 0" rpy="0 0 0" />
      <geometry>
        <mesh filename="package://mrx_t4_a00_new/meshes/armA.STL" />
      </geometry>
    </collision>
  </link>

  <joint name="armA_to_armB" type="revolute">
    <origin xyz="0 -0.113 0.03375" rpy="0 -1.5708 0" />
    <parent link="armA" />
    <child link="armB" />
    <axis xyz="-1 0 0" />
    <limit effort="300" velocity="1" lower="-1.5708" upper="0.349065" />
  </joint>

  <link
    name="armB">
    <inertial>
      <origin xyz="0.013013 0.020769 0.15495" rpy="0 0 0" />
      <mass value="0.33565" />
      <inertia
        ixx="0.0042212"
        ixy="2.1585E-05"
        ixz="0.00030616"
        iyy="0.0041857"
        iyz="-1.0585E-05"
        izz="0.0011326" />
    </inertial>
    <visual>
      <origin xyz="0 0 0" rpy="0 0 0" />
      <geometry>
        <mesh filename="package://mrx_t4_a00_new/meshes/armB.STL" />
      </geometry>
      <material name="">
        <color rgba="0.69804 0.69804 0.69804 1" />
      </material>
    </visual>
    <collision>
      <origin xyz="0 0 0" rpy="0 0 0" />
      <geometry>
        <mesh filename="package://mrx_t4_a00_new/meshes/armB.STL" />
      </geometry>
    </collision>
  </link>

  <joint name="armB_to_armC" type="revolute">
    <origin xyz="-0.06375 -0.255 0" rpy="0 1.5708 0" />
    <parent link="armB" />
    <child link="armC" />
    <axis xyz="0 0 -1" />
    <limit effort="300" velocity="1" lower="-2.0944" upper="2.0944" />
  </joint>

  <link
    name="armC">
    <inertial>
      <origin xyz="0.12619 -0.01285 0.015821" rpy="0 0 0" />
      <mass value="0.62172" />
      <inertia
        ixx="0.00074736"
        ixy="6.7514E-06"
        ixz="-0.000196"
        iyy="0.0072631"
        iyz="-1.2208E-05"
        izz="0.0066601" />
    </inertial>
    <visual>
      <origin
        xyz="0 0 0"
        rpy="0 0 0" />
      <geometry>
        <mesh filename="package://mrx_t4_a00_new/meshes/armC.STL" />
      </geometry>
      <material name="">
        <color rgba="0.69804 0.69804 0.69804 1" />
      </material>
    </visual>
    <collision>
      <origin xyz="0 0 0" rpy="0 0 0" />
      <geometry>
        <mesh filename="package://mrx_t4_a00_new/meshes/armC.STL" />
      </geometry>
    </collision>
  </link>

  <joint name="armC_to_armD" type="continuous">
    <origin xyz="0.25 0 0.03" rpy="1.5708 0 3.1416" />
    <parent link="armC" />
    <child link="armD" />
    <axis xyz="0 -1 0" />
  </joint>

  <link
    name="armD">
    <inertial>
      <origin xyz="7.533E-05 0.0029979 0.086356" rpy="0 0 0" />
      <mass
        value="0.30492" />
      <inertia
        ixx="0.00080442"
        ixy="2.1974E-06"
        ixz="-3.2773E-07"
        iyy="0.00087792"
        iyz="3.4916E-05"
        izz="0.00023134" />
    </inertial>
    <visual>
      <origin xyz="0 0 0" rpy="0 0 0" />
      <geometry>
        <mesh filename="package://mrx_t4_a00_new/meshes/armD.STL" />
      </geometry>
      <material name="">
        <color rgba="0.62745 0.41961 0.18824 1" />
      </material>
    </visual>
    <collision>
      <origin xyz="0 0 0" rpy="0 0 0" />
      <geometry>
        <mesh filename="package://mrx_t4_a00_new/meshes/armD.STL" />
      </geometry>
    </collision>
  </link>

</robot>
